2025-07-11 16:46:57,206 INFO    MainThread:167523 [wandb_setup.py:_flush():80] Current SDK version is 0.21.0
2025-07-11 16:46:57,206 INFO    MainThread:167523 [wandb_setup.py:_flush():80] Configure stats pid to 167523
2025-07-11 16:46:57,206 INFO    MainThread:167523 [wandb_setup.py:_flush():80] Loading settings from /home/aletolia/.config/wandb/settings
2025-07-11 16:46:57,206 INFO    MainThread:167523 [wandb_setup.py:_flush():80] Loading settings from /home/aletolia/documents/CPath/Fate/wandb/settings
2025-07-11 16:46:57,206 INFO    MainThread:167523 [wandb_setup.py:_flush():80] Loading settings from environment variables
2025-07-11 16:46:57,206 INFO    MainThread:167523 [wandb_init.py:setup_run_log_directory():703] Logging user logs to /home/aletolia/documents/CPath/Fate/wandb/run-20250711_164657-3qa6autt/logs/debug.log
2025-07-11 16:46:57,206 INFO    MainThread:167523 [wandb_init.py:setup_run_log_directory():704] Logging internal logs to /home/aletolia/documents/CPath/Fate/wandb/run-20250711_164657-3qa6autt/logs/debug-internal.log
2025-07-11 16:46:57,206 INFO    MainThread:167523 [wandb_init.py:init():830] calling init triggers
2025-07-11 16:46:57,206 INFO    MainThread:167523 [wandb_init.py:init():835] wandb.init called with sweep_config: {}
config: {'loss_weighting_strategy': 'mgda', 'use_pcgrad': False, 'use_diversity_reg': False, 'diversity_beta': 0.0001, 'use_task_norm': False, 'use_sampler': False, 'learning_rate': 0.0001, 'weight_decay': 0.0001, 'batch_size': 1, 'num_epochs': 30, 'seed': 42, 'early_stopping_patience': 10, 'early_stopping_delta': 0.0001, 'dwa_temperature': 2.0, 'folds_dir': 'folds_new', 'output_dir': './training_output', 'wandb_project': 'multitask_moe_refactored', 'wandb_run_name': None, '_wandb': {}}
2025-07-11 16:46:57,206 INFO    MainThread:167523 [wandb_init.py:init():871] starting backend
2025-07-11 16:46:57,411 INFO    MainThread:167523 [wandb_init.py:init():874] sending inform_init request
2025-07-11 16:46:57,412 INFO    MainThread:167523 [wandb_init.py:init():882] backend started and connected
2025-07-11 16:46:57,413 INFO    MainThread:167523 [wandb_init.py:init():953] updated telemetry
2025-07-11 16:46:57,416 INFO    MainThread:167523 [wandb_init.py:init():977] communicating run to backend with 90.0 second timeout
2025-07-11 16:46:58,922 INFO    MainThread:167523 [wandb_init.py:init():1029] starting run threads in backend
2025-07-11 16:46:58,993 INFO    MainThread:167523 [wandb_run.py:_console_start():2458] atexit reg
2025-07-11 16:46:58,993 INFO    MainThread:167523 [wandb_run.py:_redirect():2306] redirect: wrap_raw
2025-07-11 16:46:58,993 INFO    MainThread:167523 [wandb_run.py:_redirect():2375] Wrapping output streams.
2025-07-11 16:46:58,994 INFO    MainThread:167523 [wandb_run.py:_redirect():2398] Redirects installed.
2025-07-11 16:46:58,995 INFO    MainThread:167523 [wandb_init.py:init():1075] run started, returning control to user process
2025-07-11 16:47:28,994 INFO    MsgRouterThr:167523 [mailbox.py:close():129] [no run ID] Closing mailbox, abandoning 2 handles.
2025-07-11 16:47:31,708 ERROR   MainThread:167523 [redirect.py:_on_write():664] [all runs] error in stderr callback
Traceback (most recent call last):
  File "/home/aletolia/anaconda3/envs/fate/lib/python3.10/site-packages/wandb/sdk/lib/redirect.py", line 662, in _on_write
    cb(written_data)
  File "/home/aletolia/anaconda3/envs/fate/lib/python3.10/site-packages/wandb/sdk/wandb_run.py", line 2385, in <lambda>
    lambda data: self._console_raw_callback("stderr", data),
  File "/home/aletolia/anaconda3/envs/fate/lib/python3.10/site-packages/wandb/sdk/wandb_run.py", line 398, in wrapper
    return func(self, *args, **kwargs)
  File "/home/aletolia/anaconda3/envs/fate/lib/python3.10/site-packages/wandb/sdk/wandb_run.py", line 456, in wrapper_fn
    return func(self, *args, **kwargs)
  File "/home/aletolia/anaconda3/envs/fate/lib/python3.10/site-packages/wandb/sdk/wandb_run.py", line 1566, in _console_raw_callback
    self._backend.interface.publish_output_raw(name, data)
  File "/home/aletolia/anaconda3/envs/fate/lib/python3.10/site-packages/wandb/sdk/interface/interface.py", line 771, in publish_output_raw
    self._publish_output_raw(o)
  File "/home/aletolia/anaconda3/envs/fate/lib/python3.10/site-packages/wandb/sdk/interface/interface_shared.py", line 38, in _publish_output_raw
    self._publish(rec)
  File "/home/aletolia/anaconda3/envs/fate/lib/python3.10/site-packages/wandb/sdk/interface/interface_sock.py", line 39, in _publish
    self._sock_client.send_record_publish(record)
  File "/home/aletolia/anaconda3/envs/fate/lib/python3.10/site-packages/wandb/sdk/lib/sock_client.py", line 170, in send_record_publish
    self.send_server_request(server_req)
  File "/home/aletolia/anaconda3/envs/fate/lib/python3.10/site-packages/wandb/sdk/lib/sock_client.py", line 150, in send_server_request
    self._send_message(msg)
  File "/home/aletolia/anaconda3/envs/fate/lib/python3.10/site-packages/wandb/sdk/lib/sock_client.py", line 147, in _send_message
    self._sendall_with_error_handle(header + data)
  File "/home/aletolia/anaconda3/envs/fate/lib/python3.10/site-packages/wandb/sdk/lib/sock_client.py", line 126, in _sendall_with_error_handle
    sent = self._sock.send(data)
BrokenPipeError: [Errno 32] Broken pipe
2025-07-11 16:47:31,711 ERROR   MainThread:167523 [redirect.py:_on_write():664] [all runs] error in stderr callback
Traceback (most recent call last):
  File "/home/aletolia/anaconda3/envs/fate/lib/python3.10/site-packages/wandb/sdk/lib/redirect.py", line 662, in _on_write
    cb(written_data)
  File "/home/aletolia/anaconda3/envs/fate/lib/python3.10/site-packages/wandb/sdk/wandb_run.py", line 2385, in <lambda>
    lambda data: self._console_raw_callback("stderr", data),
  File "/home/aletolia/anaconda3/envs/fate/lib/python3.10/site-packages/wandb/sdk/wandb_run.py", line 398, in wrapper
    return func(self, *args, **kwargs)
  File "/home/aletolia/anaconda3/envs/fate/lib/python3.10/site-packages/wandb/sdk/wandb_run.py", line 456, in wrapper_fn
    return func(self, *args, **kwargs)
  File "/home/aletolia/anaconda3/envs/fate/lib/python3.10/site-packages/wandb/sdk/wandb_run.py", line 1566, in _console_raw_callback
    self._backend.interface.publish_output_raw(name, data)
  File "/home/aletolia/anaconda3/envs/fate/lib/python3.10/site-packages/wandb/sdk/interface/interface.py", line 771, in publish_output_raw
    self._publish_output_raw(o)
  File "/home/aletolia/anaconda3/envs/fate/lib/python3.10/site-packages/wandb/sdk/interface/interface_shared.py", line 38, in _publish_output_raw
    self._publish(rec)
  File "/home/aletolia/anaconda3/envs/fate/lib/python3.10/site-packages/wandb/sdk/interface/interface_sock.py", line 39, in _publish
    self._sock_client.send_record_publish(record)
  File "/home/aletolia/anaconda3/envs/fate/lib/python3.10/site-packages/wandb/sdk/lib/sock_client.py", line 170, in send_record_publish
    self.send_server_request(server_req)
  File "/home/aletolia/anaconda3/envs/fate/lib/python3.10/site-packages/wandb/sdk/lib/sock_client.py", line 150, in send_server_request
    self._send_message(msg)
  File "/home/aletolia/anaconda3/envs/fate/lib/python3.10/site-packages/wandb/sdk/lib/sock_client.py", line 147, in _send_message
    self._sendall_with_error_handle(header + data)
  File "/home/aletolia/anaconda3/envs/fate/lib/python3.10/site-packages/wandb/sdk/lib/sock_client.py", line 126, in _sendall_with_error_handle
    sent = self._sock.send(data)
BrokenPipeError: [Errno 32] Broken pipe
2025-07-11 16:47:31,711 ERROR   MainThread:167523 [redirect.py:_on_write():664] [all runs] error in stderr callback
Traceback (most recent call last):
  File "/home/aletolia/anaconda3/envs/fate/lib/python3.10/site-packages/wandb/sdk/lib/redirect.py", line 662, in _on_write
    cb(written_data)
  File "/home/aletolia/anaconda3/envs/fate/lib/python3.10/site-packages/wandb/sdk/wandb_run.py", line 2385, in <lambda>
    lambda data: self._console_raw_callback("stderr", data),
  File "/home/aletolia/anaconda3/envs/fate/lib/python3.10/site-packages/wandb/sdk/wandb_run.py", line 398, in wrapper
    return func(self, *args, **kwargs)
  File "/home/aletolia/anaconda3/envs/fate/lib/python3.10/site-packages/wandb/sdk/wandb_run.py", line 456, in wrapper_fn
    return func(self, *args, **kwargs)
  File "/home/aletolia/anaconda3/envs/fate/lib/python3.10/site-packages/wandb/sdk/wandb_run.py", line 1566, in _console_raw_callback
    self._backend.interface.publish_output_raw(name, data)
  File "/home/aletolia/anaconda3/envs/fate/lib/python3.10/site-packages/wandb/sdk/interface/interface.py", line 771, in publish_output_raw
    self._publish_output_raw(o)
  File "/home/aletolia/anaconda3/envs/fate/lib/python3.10/site-packages/wandb/sdk/interface/interface_shared.py", line 38, in _publish_output_raw
    self._publish(rec)
  File "/home/aletolia/anaconda3/envs/fate/lib/python3.10/site-packages/wandb/sdk/interface/interface_sock.py", line 39, in _publish
    self._sock_client.send_record_publish(record)
  File "/home/aletolia/anaconda3/envs/fate/lib/python3.10/site-packages/wandb/sdk/lib/sock_client.py", line 170, in send_record_publish
    self.send_server_request(server_req)
  File "/home/aletolia/anaconda3/envs/fate/lib/python3.10/site-packages/wandb/sdk/lib/sock_client.py", line 150, in send_server_request
    self._send_message(msg)
  File "/home/aletolia/anaconda3/envs/fate/lib/python3.10/site-packages/wandb/sdk/lib/sock_client.py", line 147, in _send_message
    self._sendall_with_error_handle(header + data)
  File "/home/aletolia/anaconda3/envs/fate/lib/python3.10/site-packages/wandb/sdk/lib/sock_client.py", line 126, in _sendall_with_error_handle
    sent = self._sock.send(data)
BrokenPipeError: [Errno 32] Broken pipe
2025-07-11 16:47:31,711 ERROR   MainThread:167523 [redirect.py:_on_write():664] [all runs] error in stderr callback
Traceback (most recent call last):
  File "/home/aletolia/anaconda3/envs/fate/lib/python3.10/site-packages/wandb/sdk/lib/redirect.py", line 662, in _on_write
    cb(written_data)
  File "/home/aletolia/anaconda3/envs/fate/lib/python3.10/site-packages/wandb/sdk/wandb_run.py", line 2385, in <lambda>
    lambda data: self._console_raw_callback("stderr", data),
  File "/home/aletolia/anaconda3/envs/fate/lib/python3.10/site-packages/wandb/sdk/wandb_run.py", line 398, in wrapper
    return func(self, *args, **kwargs)
  File "/home/aletolia/anaconda3/envs/fate/lib/python3.10/site-packages/wandb/sdk/wandb_run.py", line 456, in wrapper_fn
    return func(self, *args, **kwargs)
  File "/home/aletolia/anaconda3/envs/fate/lib/python3.10/site-packages/wandb/sdk/wandb_run.py", line 1566, in _console_raw_callback
    self._backend.interface.publish_output_raw(name, data)
  File "/home/aletolia/anaconda3/envs/fate/lib/python3.10/site-packages/wandb/sdk/interface/interface.py", line 771, in publish_output_raw
    self._publish_output_raw(o)
  File "/home/aletolia/anaconda3/envs/fate/lib/python3.10/site-packages/wandb/sdk/interface/interface_shared.py", line 38, in _publish_output_raw
    self._publish(rec)
  File "/home/aletolia/anaconda3/envs/fate/lib/python3.10/site-packages/wandb/sdk/interface/interface_sock.py", line 39, in _publish
    self._sock_client.send_record_publish(record)
  File "/home/aletolia/anaconda3/envs/fate/lib/python3.10/site-packages/wandb/sdk/lib/sock_client.py", line 170, in send_record_publish
    self.send_server_request(server_req)
  File "/home/aletolia/anaconda3/envs/fate/lib/python3.10/site-packages/wandb/sdk/lib/sock_client.py", line 150, in send_server_request
    self._send_message(msg)
  File "/home/aletolia/anaconda3/envs/fate/lib/python3.10/site-packages/wandb/sdk/lib/sock_client.py", line 147, in _send_message
    self._sendall_with_error_handle(header + data)
  File "/home/aletolia/anaconda3/envs/fate/lib/python3.10/site-packages/wandb/sdk/lib/sock_client.py", line 126, in _sendall_with_error_handle
    sent = self._sock.send(data)
BrokenPipeError: [Errno 32] Broken pipe
2025-07-11 16:47:31,711 ERROR   MainThread:167523 [redirect.py:_on_write():664] [all runs] error in stderr callback
Traceback (most recent call last):
  File "/home/aletolia/anaconda3/envs/fate/lib/python3.10/site-packages/wandb/sdk/lib/redirect.py", line 662, in _on_write
    cb(written_data)
  File "/home/aletolia/anaconda3/envs/fate/lib/python3.10/site-packages/wandb/sdk/wandb_run.py", line 2385, in <lambda>
    lambda data: self._console_raw_callback("stderr", data),
  File "/home/aletolia/anaconda3/envs/fate/lib/python3.10/site-packages/wandb/sdk/wandb_run.py", line 398, in wrapper
    return func(self, *args, **kwargs)
  File "/home/aletolia/anaconda3/envs/fate/lib/python3.10/site-packages/wandb/sdk/wandb_run.py", line 456, in wrapper_fn
    return func(self, *args, **kwargs)
  File "/home/aletolia/anaconda3/envs/fate/lib/python3.10/site-packages/wandb/sdk/wandb_run.py", line 1566, in _console_raw_callback
    self._backend.interface.publish_output_raw(name, data)
  File "/home/aletolia/anaconda3/envs/fate/lib/python3.10/site-packages/wandb/sdk/interface/interface.py", line 771, in publish_output_raw
    self._publish_output_raw(o)
  File "/home/aletolia/anaconda3/envs/fate/lib/python3.10/site-packages/wandb/sdk/interface/interface_shared.py", line 38, in _publish_output_raw
    self._publish(rec)
  File "/home/aletolia/anaconda3/envs/fate/lib/python3.10/site-packages/wandb/sdk/interface/interface_sock.py", line 39, in _publish
    self._sock_client.send_record_publish(record)
  File "/home/aletolia/anaconda3/envs/fate/lib/python3.10/site-packages/wandb/sdk/lib/sock_client.py", line 170, in send_record_publish
    self.send_server_request(server_req)
  File "/home/aletolia/anaconda3/envs/fate/lib/python3.10/site-packages/wandb/sdk/lib/sock_client.py", line 150, in send_server_request
    self._send_message(msg)
  File "/home/aletolia/anaconda3/envs/fate/lib/python3.10/site-packages/wandb/sdk/lib/sock_client.py", line 147, in _send_message
    self._sendall_with_error_handle(header + data)
  File "/home/aletolia/anaconda3/envs/fate/lib/python3.10/site-packages/wandb/sdk/lib/sock_client.py", line 126, in _sendall_with_error_handle
    sent = self._sock.send(data)
BrokenPipeError: [Errno 32] Broken pipe
